Workbook

Sheet Sheet6
A1: No | B1: Kabupaten/Kota | C1: PDRB ADHK
A2: 1 | B2: Kabupaten Cilacap | C2: 100327.3
A3: 2 | B3: Kabupaten Banyumas | C3: 39779.32
A4: 3 | B4: Kabupaten Purbalingga | C4: 17387.61
A5: 4 | B5: Kabupaten Banjarnegara | C5: 15246.87
A6: 5 | B6: Kabupaten Kebumen | C6: 19815.06
A7: 6 | B7: Kabupaten Purworejo | C7: 13353.34
A8: 7 | B8: Kabupaten Wonosobo | C8: 13793.04
A9: 8 | B9: Kabupaten Magelang | C9: 23253.15
A10: 9 | B10: Kabupaten Boyolali | C10: 22681.1
A11: 10 | B11: Kabupaten Klaten | C11: 27805.99
A12: 11 | B12: Kabupaten Sukoharjo | C12: 27076.44
A13: 12 | B13: Kabupaten Wonogiri | C13: 20856.21
... A36: 35 | B36: Kota Tegal | C36: 11205.78
A37: Provinsi Jawa Tengah | C37: =SUM(C2:C36) -> 990170.01

Sheet PDRB Perkapita_Smrg

Sheet 2020
A1: PDRB Atas Dasar Harga Konstan (Milyar Rupiah) dan Pertumbuhan Ekonomi (Persen) Kabupaten/Kota di Jawa Tengah
A2: No | B2: Kabupaten/Kota | C2: PDRB ADHK | D2: Pertumbuhan Ekonomi
A3: 1 | B3: Kabupaten Cilacap | C3: 90011.58 | D3: =((C3-Sheet6!C2)/Sheet6!C2)*100 -> -10.282067
A4: 2 | B4: Kabupaten Banyumas | C4: 39121.62 | D4: =((C4-Sheet6!C3)/Sheet6!C3)*100 -> -1.6533717
A5: 3 | B5: Kabupaten Purbalingga | C5: 17182.87 | D5: =((C5-Sheet6!C4)/Sheet6!C4)*100 -> -1.1775051
A6: 4 | B6: Kabupaten Banjarnegara | C6: 15045.88 | D6: =((C6-Sheet6!C5)/Sheet6!C5)*100 -> -1.3182378
A7: 5 | B7: Kabupaten Kebumen | C7: 19527.66 | D7: =((C7-Sheet6!C6)/Sheet6!C6)*100 -> -1.450412
A8: 6 | B8: Kabupaten Purworejo | C8: 13138.29 | D8: =((C8-Sheet6!C7)/Sheet6!C7)*100 -> -1.6104585
A9: 7 | B9: Kabupaten Wonosobo | C9: 13566.18 | D9: =((C9-Sheet6!C8)/Sheet6!C8)*100 -> -1.6447426
A10: 8 | B10: Kabupaten Magelang | C10: 22865.15 | D10: =((C10-Sheet6!C9)/Sheet6!C9)*100 -> -1.6685911
A11: 9 | B11: Kabupaten Boyolali | C11: 22409.73 | D11: =((C11-Sheet6!C10)/Sheet6!C10)*100 -> -1.1964587
A12: 10 | B12: Kabupaten Klaten | C12: 27480.36 | D12: =((C12-Sheet6!C11)/Sheet6!C11)*100 -> -1.1710786
A13: 11 | B13: Kabupaten Sukoharjo | C13: 26616.5 | D13: =((C13-Sheet6!C12)/Sheet6!C12)*100 -> -1.6986724
A14: 12 | B14: Kabupaten Wonogiri | C14: 20563.14 | D14: =((C14-Sheet6!C13)/Sheet6!C13)*100 -> -1.405193
... A37: 35 | B37: Kota Tegal | C37: 10949.12 | D37: =((C37-Sheet6!C36)/Sheet6!C36)*100 -> -2.2904251
A38: Provinsi Jawa Tengah | C38: =SUM(C3:C37) -> 964084.22 | D38: =((C38-Sheet6!C37)/Sheet6!C37)*100 -> -2.6344759

Sheet 2021
A1: PDRB Atas Dasar Harga Konstan (Milyar Rupiah) dan Pertumbuhan Ekonomi (Persen) Kabupaten/Kota di Jawa Tengah
A2: No | B2: Kabupaten/Kota | C2: PDRB ADHK | D2: Pertumbuhan Ekonomi
A3: 1 | B3: Kabupaten Cilacap | C3: 91944.59 | D3: =((C3-'2020'!C3)/'2020'!C3)*100 -> 2.1475126
A4: 2 | B4: Kabupaten Banyumas | C4: 40686.81 | D4: =((C4-'2020'!C4)/'2020'!C4)*100 -> 4.0008313
A5: 3 | B5: Kabupaten Purbalingga | C5: 17731.44 | D5: =((C5-'2020'!C5)/'2020'!C5)*100 -> 3.19254
A6: 4 | B6: Kabupaten Banjarnegara | C6: 15536.48 | D6: =((C6-'2020'!C6)/'2020'!C6)*100 -> 3.2606933
A7: 5 | B7: Kabupaten Kebumen | C7: 20253.06 | D7: =((C7-'2020'!C7)/'2020'!C7)*100 -> 3.7147308
A8: 6 | B8: Kabupaten Purworejo | C8: 13573.47 | D8: =((C8-'2020'!C8)/'2020'!C8)*100 -> 3.3123032
A9: 7 | B9: Kabupaten Wonosobo | C9: 14064.76 | D9: =((C9-'2020'!C9)/'2020'!C9)*100 -> 3.6751687
A10: 8 | B10: Kabupaten Magelang | C10: 23661.71 | D10: =((C10-'2020'!C10)/'2020'!C10)*100 -> 3.4837296
A11: 9 | B11: Kabupaten Boyolali | C11: 23447.37 | D11: =((C11-'2020'!C11)/'2020'!C11)*100 -> 4.6303101
A12: 10 | B12: Kabupaten Klaten | C12: 28531.11 | D12: =((C12-'2020'!C12)/'2020'!C12)*100 -> 3.8236399
A13: 11 | B13: Kabupaten Sukoharjo | C13: 27634.12 | D13: =((C13-'2020'!C13)/'2020'!C13)*100 -> 3.8232675
A14: 12 | B14: Kabupaten Wonogiri | C14: 21251.17 | D14: =((C14-'2020'!C14)/'2020'!C14)*100 -> 3.3459384
... A37: 35 | B37: Kota Tegal | C37: 11290.27 | D37: =((C37-'2020'!C37)/'2020'!C37)*100 -> 3.1157755
A38: Provinsi Jawa Tengah | C38: =SUM(C3:C37) -> 996470.57 | D38: =((C38-'2020'!C38)/'2020'!C38)*100 -> 3.3592864

Sheet 2022
A1: PDRB Atas Dasar Harga Konstan (Milyar Rupiah) dan Pertumbuhan Ekonomi (Persen) Kabupaten/Kota di Jawa Tengah | G1: PDRB Atas Dasar Harga Konstan (Milyar Rupiah) dan Pertumbuhan Ekonomi (Persen) Kabupaten/Kota di Jawa Tengah 6 maret 2026
A2: No | B2: Kabupaten/Kota | C2: PDRB ADHK | D2: Pertumbuhan Ekonomi | G2: No | H2: Kabupaten/Kota | I2: PDRB ADHK | J2: Pertumbuhan Ekonomi | K2: Kontribusi PDRB
A3: 1 | B3: Kabupaten Cilacap | C3: 96677.84 | D3: =((C3-'2021'!C3)/'2021'!C3)*100 -> 5.1479375 | G3: 1 | H3: Kabupaten Cilacap | I3: 96677.84 | J3: =((I3-'2021'!C3)/'2021'!C3)*100 -> 5.1479375 | K3: =I3/$I$38*100 -> 9.2049754
A4: 2 | B4: Kabupaten Banyumas | C4: 43069.5 | D4: =((C4-'2021'!C4)/'2021'!C4)*100 -> 5.856173 | G4: 2 | H4: Kabupaten Banyumas | I4: 43069.5 | J4: =((I4-'2021'!C4)/'2021'!C4)*100 -> 5.856173 | K4: =I4/$I$38*100 -> 4.1007711
A5: 3 | B5: Kabupaten Purbalingga | C5: 18690.73 | D5: =((C5-'2021'!C5)/'2021'!C5)*100 -> 5.4101077 | G5: 3 | H5: Kabupaten Purbalingga | I5: 18690.73 | J5: =((I5-'2021'!C5)/'2021'!C5)*100 -> 5.4101077 | K5: =I5/$I$38*100 -> 1.7795982
A6: 4 | B6: Kabupaten Banjarnegara | C6: 16359.11 | D6: =((C6-'2021'!C6)/'2021'!C6)*100 -> 5.2948287 | G6: 4 | H6: Kabupaten Banjarnegara | I6: 16359.11 | J6: =((I6-'2021'!C6)/'2021'!C6)*100 -> 5.2948287 | K6: =I6/$I$38*100 -> 1.5575979
A7: 5 | B7: Kabupaten Kebumen | C7: 21425.79 | D7: =((C7-'2021'!C7)/'2021'!C7)*100 -> 5.7903843 | G7: 5 | H7: Kabupaten Kebumen | I7: 21425.79 | J7: =((I7-'2021'!C7)/'2021'!C7)*100 -> 5.7903843 | K7: =I7/$I$38*100 -> 2.0400111
A8: 6 | B8: Kabupaten Purworejo | C8: 14300.56 | D8: =((C8-'2021'!C8)/'2021'!C8)*100 -> 5.3566995 | G8: 6 | H8: Kabupaten Purworejo | I8: 14300.56 | J8: =((I8-'2021'!C8)/'2021'!C8)*100 -> 5.3566995 | K8: =I8/$I$38*100 -> 1.3615975
A9: 7 | B9: Kabupaten Wonosobo | C9: 14770.5 | D9: =((C9-'2021'!C9)/'2021'!C9)*100 -> 5.0177891 | G9: 7 | H9: Kabupaten Wonosobo | I9: 14770.5 | J9: =((I9-'2021'!C9)/'2021'!C9)*100 -> 5.0177891 | K9: =I9/$I$38*100 -> 1.4063418
A10: 8 | B10: Kabupaten Magelang | C10: 24953.18 | D10: =((C10-'2021'!C10)/'2021'!C10)*100 -> 5.4580586 | G10: 8 | H10: Kabupaten Magelang | I10: 24953.18 | J10: =((I10-'2021'!C10)/'2021'!C10)*100 -> 5.4580586 | K10: =I10/$I$38*100 -> 2.3758641
A11: 9 | B11: Kabupaten Boyolali | C11: 24931.3 | D11: =((C11-'2021'!C11)/'2021'!C11)*100 -> 6.3287695 | G11: 9 | H11: Kabupaten Boyolali | I11: 24931.3 | J11: =((I11-'2021'!C11)/'2021'!C11)*100 -> 6.3287695 | K11: =I11/$I$38*100 -> 2.3737808
A12: 10 | B12: Kabupaten Klaten | C12: 30214.98 | D12: =((C12-'2021'!C12)/'2021'!C12)*100 -> 5.9018734 | G12: 10 | H12: Kabupaten Klaten | I12: 30214.98 | J12: =((I12-'2021'!C12)/'2021'!C12)*100 -> 5.9018734 | K12: =I12/$I$38*100 -> 2.8768552
A13: 11 | B13: Kabupaten Sukoharjo | C13: 29185.35 | D13: =((C13-'2021'!C13)/'2021'!C13)*100 -> 5.613459 | G13: 11 | H13: Kabupaten Sukoharjo | I13: 29185.35 | J13: =((I13-'2021'!C13)/'2021'!C13)*100 -> 5.613459 | K13: =I13/$I$38*100 -> 2.7788212
A14: 12 | B14: Kabupaten Wonogiri | C14: 22448.63 | D14: =((C14-'2021'!C14)/'2021'!C14)*100 -> 5.6347956 | G14: 12 | H14: Kabupaten Wonogiri | I14: 22448.63 | J14: =((I14-'2021'!C14)/'2021'!C14)*100 -> 5.6347956 | K14: =I14/$I$38*100 -> 2.1373987
... A37: 35 | B37: Kota Tegal | C37: 11873.2 | D37: =((C37-'2021'!C37)/'2021'!C37)*100 -> 5.1631183 | G37: 35 | H37: Kota Tegal | I37: 11873.2 | J37: =((I37-'2021'!C37)/'2021'!C37)*100 -> 5.1631183 | K37: =I37/$I$38*100 -> 1.1304815
A38: Provinsi Jawa Tengah | C38: =SUM(C3:C37) -> 1049295.1 | D38: =((C38-'2021'!C38)/'2021'!C38)*100 -> 5.3011621 | G38: Provinsi Jawa Tengah | I38: 1050278.1 | J38: =((I38-'2021'!C38)/'2021'!C38)*100 -> 5.3998103 | K38: =I38/$I$38*100 -> 100
E42: Sektor PDRB Lapangan Usaha Tahun Dasar 2010 | F42: [Seri 2010] Distribusi PDRB Atas Dasar Harga Berlaku Menurut Lapangan Usaha (Persen)_2022 (Sektor Utama Terbesar)
E43: A. Pertanian, Kehutanan, dan Perikanan | F43: 0.81
E44: B. Pertambangan dan Penggalian | F44: 0.16
E45: C. Industri Pengolahan | F45: 28.87
E46: D. Pengadaan Listrik dan Gas | F46: 0.09
E47: E. Pengadaan Air, Pengelolaan Sampah, Limbah dan Daur Ulang | F47: 0.07
E48: F. Konstruksi | F48: 26.33
E49: G. Perdagangan Besar dan Eceran; Reparasi Mobil dan Sepeda Motor | F49: 13.2
E50: H. Transportasi dan Pergudangan | F50: 4.17
E51: I. Penyediaan Akomodasi dan Makan Minum | F51: 3.07
E52: J. Informasi dan Komunikasi | F52: 8.62
E53: K. Jasa Keuangan dan Asuransi | F53: 4.19
E54: L. Real Estate | F54: 2.68
... E60: PDRB | F60: 100

Sheet 2023
A1: PDRB Atas Dasar Harga Konstan (Milyar Rupiah) dan Pertumbuhan Ekonomi (Persen) Kabupaten/Kota di Jawa Tengah | G1: PDRB Atas Dasar Harga Konstan (Milyar Rupiah) dan Pertumbuhan Ekonomi (Persen) Kabupaten/Kota di Jawa Tengah 6 maret 2026
A2: No | B2: Kabupaten/Kota | C2: PDRB ADHK | D2: Pertumbuhan Ekonomi | G2: No | H2: Kabupaten/Kota | I2: PDRB ADHK | J2: Pertumbuhan Ekonomi | K2: Kontribusi PDRB
A3: 1 | B3: Kabupaten Cilacap | C3: 101839.74 | D3: =((C3-'2022'!C3)/'2022'!C3)*100 -> 5.3392794 | G3: 1 | H3: Kabupaten Cilacap | I3: 101816.53 | J3: =((I3-'2022'!C3)/'2022'!C3)*100 -> 5.3152718 | K3: =I3/$I$38*100 -> 9.2355831
A4: 2 | B4: Kabupaten Banyumas | C4: 45396.3 | D4: =((C4-'2022'!C4)/'2022'!C4)*100 -> 5.402431 | G4: 2 | H4: Kabupaten Banyumas | I4: 45386.22 | J4: =((I4-'2022'!C4)/'2022'!C4)*100 -> 5.3790269 | K4: =I4/$I$38*100 -> 4.1168974
A5: 3 | B5: Kabupaten Purbalingga | C5: 19533.86 | D5: =((C5-'2022'!C5)/'2022'!C5)*100 -> 4.5109528 | G5: 3 | H5: Kabupaten Purbalingga | I5: 19525.36 | J5: =((I5-'2022'!C5)/'2022'!C5)*100 -> 4.4654757 | K5: =I5/$I$38*100 -> 1.7711081
A6: 4 | B6: Kabupaten Banjarnegara | C6: 17174.39 | D6: =((C6-'2022'!C6)/'2022'!C6)*100 -> 4.9836452 | G6: 4 | H6: Kabupaten Banjarnegara | I6: 17174.39 | J6: =((I6-'2022'!C6)/'2022'!C6)*100 -> 4.9836452 | K6: =I6/$I$38*100 -> 1.5578561
A7: 5 | B7: Kabupaten Kebumen | C7: 22638.9 | D7: =((C7-'2022'!C7)/'2022'!C7)*100 -> 5.6619149 | G7: 5 | H7: Kabupaten Kebumen | I7: 22630.06 | J7: =((I7-'2022'!C7)/'2022'!C7)*100 -> 5.6206562 | K7: =I7/$I$38*100 -> 2.0527295
A8: 6 | B8: Kabupaten Purworejo | C8: 15025.91 | D8: =((C8-'2022'!C8)/'2022'!C8)*100 -> 5.072179 | G8: 6 | H8: Kabupaten Purworejo | I8: 15025.64 | J8: =((I8-'2022'!C8)/'2022'!C8)*100 -> 5.070291 | K8: =I8/$I$38*100 -> 1.3629471
A9: 7 | B9: Kabupaten Wonosobo | C9: 15405.98 | D9: =((C9-'2022'!C9)/'2022'!C9)*100 -> 4.3023594 | G9: 7 | H9: Kabupaten Wonosobo | I9: 15405.03 | J9: =((I9-'2022'!C9)/'2022'!C9)*100 -> 4.2959277 | K9: =I9/$I$38*100 -> 1.3973609
A10: 8 | B10: Kabupaten Magelang | C10: 26211.56 | D10: =((C10-'2022'!C10)/'2022'!C10)*100 -> 5.0429645 | G10: 8 | H10: Kabupaten Magelang | I10: 26207.91 | J10: =((I10-'2022'!C10)/'2022'!C10)*100 -> 5.0283371 | K10: =I10/$I$38*100 -> 2.3772695
A11: 9 | B11: Kabupaten Boyolali | C11: 26333.28 | D11: =((C11-'2022'!C11)/'2022'!C11)*100 -> 5.623373 | G11: 9 | H11: Kabupaten Boyolali | I11: 26326.85 | J11: =((I11-'2022'!C11)/'2022'!C11)*100 -> 5.5975822 | K11: =I11/$I$38*100 -> 2.3880583
A12: 10 | B12: Kabupaten Klaten | C12: 31938.33 | D12: =((C12-'2022'!C12)/'2022'!C12)*100 -> 5.7036278 | G12: 10 | H12: Kabupaten Klaten | I12: 31930.3 | J12: =((I12-'2022'!C12)/'2022'!C12)*100 -> 5.6770516 | K12: =I12/$I$38*100 -> 2.8963366
A13: 11 | B13: Kabupaten Sukoharjo | C13: 30662.65 | D13: =((C13-'2022'!C13)/'2022'!C13)*100 -> 5.0617861 | G13: 11 | H13: Kabupaten Sukoharjo | I13: 30657.93 | J13: =((I13-'2022'!C13)/'2022'!C13)*100 -> 5.0456136 | K13: =I13/$I$38*100 -> 2.7809223
A14: 12 | B14: Kabupaten Wonogiri | C14: 23566.88 | D14: =((C14-'2022'!C14)/'2022'!C14)*100 -> 4.981373 | G14: 12 | H14: Kabupaten Wonogiri | I14: 23568.41 | J14: =((I14-'2022'!C14)/'2022'!C14)*100 -> 4.9881886 | K14: =I14/$I$38*100 -> 2.1378455
... A37: 35 | B37: Kota Tegal | C37: 12468.61 | D37: =((C37-'2022'!C37)/'2022'!C37)*100 -> 5.0147391 | G37: 35 | H37: Kota Tegal | I37: 12468.61 | J37: =((I37-'2022'!C37)/'2022'!C37)*100 -> 5.0147391 | K37: =I37/$I$38*100 -> 1.1310038
A38: Provinsi Jawa Tengah | C38: =SUM(C3:C37) -> 1101638.5 | D38: =((C38-'2022'!C38)/'2022'!C38)*100 -> 4.9884347 | G38: Provinsi Jawa Tengah | I38: 1102437.5 | J38: =((I38-'2022'!C38)/'2022'!C38)*100 -> 5.064581 | K38: =I38/$I$38*100 -> 100 | L38: 1102437.5
G41: Kontribusi PDRB
F42: Perlu dibuatkan tabel baru | G42: Sektor Perdagangan | H42: (Sektor utama penyumbang pertumbuhan ekonomi di kota smrg, yg terbesar)
G43: Nilai PDRB Perkapita
F44: Ditanyakan k mas fiqi | G44: TPT
G45: Peringkat PDRB Jawa Tengah
F47: II | G47: Sektor PDRB Lapangan Usaha Tahun Dasar 2010 | H47: [Seri 2010] Distribusi PDRB Atas Dasar Harga Berlaku Menurut Lapangan Usaha (Persen)_2023 (Sektor Utama Terbesar)
G48: A. Pertanian, Kehutanan, dan Perikanan | H48: 0.78
G49: B. Pertambangan dan Penggalian | H49: 0.16
G50: C. Industri Pengolahan | H50: 28.79
G51: D. Pengadaan Listrik dan Gas | H51: 0.09
G52: E. Pengadaan Air, Pengelolaan Sampah, Limbah dan Daur Ulang | H52: 0.07
G53: F. Konstruksi | H53: 26.43
G54: G. Perdagangan Besar dan Eceran; Reparasi Mobil dan Sepeda Motor | H54: 13.09
G55: H. Transportasi dan Pergudangan | H55: 4.62
G56: I. Penyediaan Akomodasi dan Makan Minum | H56: 3.2
G57: J. Informasi dan Komunikasi | H57: 8.55
G58: K. Jasa Keuangan dan Asuransi | H58: 3.97
G59: L. Real Estate | H59: 2.64
... G65: PDRB | H65: 100

Sheet 2024
A1: PDRB Atas Dasar Harga Konstan (Milyar Rupiah) dan Pertumbuhan Ekonomi (Persen) Kabupaten/Kota di Jawa Tengah | F1: PDRB Atas Dasar Harga Konstan (Milyar Rupiah) dan Pertumbuhan Ekonomi (Persen) Kabupaten/Kota di Jawa Tengah 6 maret 2026
A2: No | B2: Kabupaten/Kota | C2: PDRB ADHK | D2: Pertumbuhan Ekonomi | F2: No | G2: Kabupaten/Kota | H2: PDRB ADHK | I2: Pertumbuhan Ekonomi | J2: Kontribusi PDRB
A3: 1 | B3: Kabupaten Cilacap | C3: 104540.67 | D3: =((C3-'2023'!C3)/'2023'!C3)*100 -> 2.6521376 | F3: 1 | G3: Kabupaten Cilacap | H3: 104565.53 | I3: =((H3-'2023'!I3)/'2023'!I3)*100 -> 2.6999545 | J3: =H3/$H$38*100 -> 9.0376518
A4: 2 | B4: Kabupaten Banyumas | C4: 47795.71 | D4: =((C4-'2023'!C4)/'2023'!C4)*100 -> 5.2854748 | F4: 2 | G4: Kabupaten Banyumas | H4: 47815.82 | I4: =((H4-'2023'!I4)/'2023'!I4)*100 -> 5.3531667 | J4: =H4/$H$38*100 -> 4.1327456
A5: 3 | B5: Kabupaten Purbalingga | C5: 20422.61 | D5: =((C5-'2023'!C5)/'2023'!C5)*100 -> 4.549792 | F5: 3 | G5: Kabupaten Purbalingga | H5: 20417.23 | I5: =((H5-'2023'!I5)/'2023'!I5)*100 -> 4.5677519 | J5: =H5/$H$38*100 -> 1.7646715
A6: 4 | B6: Kabupaten Banjarnegara | C6: 18051.84 | D6: =((C6-'2023'!C6)/'2023'!C6)*100 -> 5.1090606 | F6: 4 | G6: Kabupaten Banjarnegara | H6: 18059.43 | I6: =((H6-'2023'!I6)/'2023'!I6)*100 -> 5.1532544 | J6: =H6/$H$38*100 -> 1.5608857
A7: 5 | B7: Kabupaten Kebumen | C7: 23837.83 | D7: =((C7-'2023'!C7)/'2023'!C7)*100 -> 5.2958845 | F7: 5 | G7: Kabupaten Kebumen | H7: 23847.86 | I7: =((H7-'2023'!I7)/'2023'!I7)*100 -> 5.3813379 | J7: =H7/$H$38*100 -> 2.0611826
A8: 6 | B8: Kabupaten Purworejo | C8: 15745.98 | D8: =((C8-'2023'!C8)/'2023'!C8)*100 -> 4.792189 | F8: 6 | G8: Kabupaten Purworejo | H8: 15753.02 | I8: =((H8-'2023'!I8)/'2023'!I8)*100 -> 4.8409252 | J8: =H8/$H$38*100 -> 1.3615415
A9: 7 | B9: Kabupaten Wonosobo | C9: 16109.38 | D9: =((C9-'2023'!C9)/'2023'!C9)*100 -> 4.5657595 | F9: 7 | G9: Kabupaten Wonosobo | H9: 16116.16 | I9: =((H9-'2023'!I9)/'2023'!I9)*100 -> 4.6162195 | J9: =H9/$H$38*100 -> 1.3929279
A10: 8 | B10: Kabupaten Magelang | C10: 27538.21 | D10: =((C10-'2023'!C10)/'2023'!C10)*100 -> 5.0613165 | F10: 8 | G10: Kabupaten Magelang | H10: 27538.45 | I10: =((H10-'2023'!I10)/'2023'!I10)*100 -> 5.0768642 | J10: =H10/$H$38*100 -> 2.3801622
A11: 9 | B11: Kabupaten Boyolali | C11: 27556.18 | D11: =((C11-'2023'!C11)/'2023'!C11)*100 -> 4.6439335 | F11: 9 | G11: Kabupaten Boyolali | H11: 27562.18 | I11: =((H11-'2023'!I11)/'2023'!I11)*100 -> 4.6922818 | J11: =H11/$H$38*100 -> 2.3822132
A12: 10 | B12: Kabupaten Klaten | C12: 33568.92 | D12: =((C12-'2023'!C12)/'2023'!C12)*100 -> 5.1054329 | F12: 10 | G12: Kabupaten Klaten | H12: 33580.87 | I12: =((H12-'2023'!I12)/'2023'!I12)*100 -> 5.1692906 | J12: =H12/$H$38*100 -> 2.9024116
A13: 11 | B13: Kabupaten Sukoharjo | C13: 32187.41 | D13: =((C13-'2023'!C13)/'2023'!C13)*100 -> 4.9726948 | F13: 11 | G13: Kabupaten Sukoharjo | H13: 32188.46 | I13: =((H13-'2023'!I13)/'2023'!I13)*100 -> 4.992281 | J13: =H13/$H$38*100 -> 2.7820649
A14: 12 | B14: Kabupaten Wonogiri | C14: 24728.69 | D14: =((C14-'2023'!C14)/'2023'!C14)*100 -> 4.9298422 | F14: 12 | G14: Kabupaten Wonogiri | H14: 24739.08 | I14: =((H14-'2023'!I14)/'2023'!I14)*100 -> 4.9671149 | J14: =H14/$H$38*100 -> 2.1382112
... A37: 35 | B37: Kota Tegal | C37: 13119.7 | D37: =((C37-'2023'!C37)/'2023'!C37)*100 -> 5.2218331 | F37: 35 | G37: Kota Tegal | H37: 13125.22 | I37: =((H37-'2023'!I37)/'2023'!I37)*100 -> 5.2661042 | J37: =H37/$H$38*100 -> 1.1344194
A38: Provinsi Jawa Tengah | C38: =SUM(C3:C37) -> 1154234 | D38: =((C38-'2023'!C38)/'2023'!C38)*100 -> 4.7743021 | F38: Provinsi Jawa Tengah | H38: 1156998.9 | I38: =((H38-'2023'!I38)/'2023'!I38)*100 -> 4.9491595 | J38: =H38/$H$38*100 -> 100
K40: 1156998.9
F42: II | G42: Sektor PDRB Lapangan Usaha Tahun Dasar 2010 | H42: [Seri 2010] Distribusi PDRB Atas Dasar Harga Berlaku Menurut Lapangan Usaha (Persen)_2024 (Sektor Utama Terbesar)
G43: A. Pertanian, Kehutanan, dan Perikanan | H43: 0.75
G44: B. Pertambangan dan Penggalian | H44: 0.15
G45: C. Industri Pengolahan | H45: 28.39
G46: D. Pengadaan Listrik dan Gas | H46: 0.09
G47: E. Pengadaan Air, Pengelolaan Sampah, Limbah dan Daur Ulang | H47: 0.07
G48: F. Konstruksi | H48: 26.84
G49: G. Perdagangan Besar dan Eceran; Reparasi Mobil dan Sepeda Motor | H49: 12.96
G50: H. Transportasi dan Pergudangan | H50: 4.61
G51: I. Penyediaan Akomodasi dan Makan Minum | H51: 3.23
G52: J. Informasi dan Komunikasi | H52: 8.73
G53: K. Jasa Keuangan dan Asuransi | H53: 3.78
G54: L. Real Estate | H54: 2.61
... G60: PDRB | H60: 100

Sheet 2025
A1: PDRB Atas Dasar Harga Konstan (Milyar Rupiah) dan Pertumbuhan Ekonomi (Persen) Kabupaten/Kota di Jawa Tengah | G1: PDRB Atas Dasar Harga Konstan (Milyar Rupiah) dan Pertumbuhan Ekonomi (Persen) Kabupaten/Kota di Jawa Tengah 6 maret 2026
A2: No | B2: Kabupaten/Kota | C2: PDRB ADHK | D2: Pertumbuhan Ekonomi | G2: No | H2: Kabupaten/Kota | I2: PDRB ADHK | J2: Pertumbuhan Ekonomi | K2: Kontribusi PDRB
A3: 1 | B3: Kabupaten Cilacap | C3: 108031.28 | D3: =((C3-'2024'!C3)/'2024'!C3)*100 -> 3.3389972 | G3: 1 | H3: Kabupaten Cilacap | I3: 108031.28 | J3: =((I3-'2024'!H3)/'2024'!H3)*100 -> 3.3144288 | K3: =I3/$I$38*100 -> 8.8612069
A4: 2 | B4: Kabupaten Banyumas | C4: 50668.64 | D4: =((C4-'2024'!C4)/'2024'!C4)*100 -> 6.0108533 | G4: 2 | H4: Kabupaten Banyumas | I4: 50668.64 | J4: =((I4-'2024'!H4)/'2024'!H4)*100 -> 5.9662681 | K4: =I4/$I$38*100 -> 4.1560676
A5: 3 | B5: Kabupaten Purbalingga | C5: 21626.94 | D5: =((C5-'2024'!C5)/'2024'!C5)*100 -> 5.8970425 | G5: 3 | H5: Kabupaten Purbalingga | I5: 21626.94 | J5: =((I5-'2024'!H5)/'2024'!H5)*100 -> 5.9249467 | K5: =I5/$I$38*100 -> 1.773938
A6: 4 | B6: Kabupaten Banjarnegara | C6: 19008.78 | D6: =((C6-'2024'!C6)/'2024'!C6)*100 -> 5.3010663 | G6: 4 | H6: Kabupaten Banjarnegara | I6: 19008.78 | J6: =((I6-'2024'!H6)/'2024'!H6)*100 -> 5.2568104 | K6: =I6/$I$38*100 -> 1.5591848
A7: 5 | B7: Kabupaten Kebumen | C7: 25253.4 | D7: =((C7-'2024'!C7)/'2024'!C7)*100 -> 5.9383342 | G7: 5 | H7: Kabupaten Kebumen | I7: 25253.4 | J7: =((I7-'2024'!H7)/'2024'!H7)*100 -> 5.8937783 | K7: =I7/$I$38*100 -> 2.0713964
A8: 6 | B8: Kabupaten Purworejo | C8: 16583.69 | D8: =((C8-'2024'!C8)/'2024'!C8)*100 -> 5.3201516 | G8: 6 | H8: Kabupaten Purworejo | I8: 16583.69 | J8: =((I8-'2024'!H8)/'2024'!H8)*100 -> 5.2730841 | K8: =I8/$I$38*100 -> 1.3602681
A9: 7 | B9: Kabupaten Wonosobo | C9: 16924.73 | D9: =((C9-'2024'!C9)/'2024'!C9)*100 -> 5.0613369 | G9: 7 | H9: Kabupaten Wonosobo | I9: 16924.73 | J9: =((I9-'2024'!H9)/'2024'!H9)*100 -> 5.0171381 | K9: =I9/$I$38*100 -> 1.3882418
A10: 8 | B10: Kabupaten Magelang | C10: 29160.54 | D10: =((C10-'2024'!C10)/'2024'!C10)*100 -> 5.8911963 | G10: 8 | H10: Kabupaten Magelang | I10: 29160.54 | J10: =((I10-'2024'!H10)/'2024'!H10)*100 -> 5.8902734 | K10: =I10/$I$38*100 -> 2.3918774
A11: 9 | B11: Kabupaten Boyolali | C11: 28890.03 | D11: =((C11-'2024'!C11)/'2024'!C11)*100 -> 4.840475 | G11: 9 | H11: Kabupaten Boyolali | I11: 28890.03 | J11: =((I11-'2024'!H11)/'2024'!H11)*100 -> 4.8176523 | K11: =I11/$I$38*100 -> 2.369689
A12: 10 | B12: Kabupaten Klaten | C12: 35131.44 | D12: =((C12-'2024'!C12)/'2024'!C12)*100 -> 4.6546627 | G12: 10 | H12: Kabupaten Klaten | I12: 35131.44 | J12: =((I12-'2024'!H12)/'2024'!H12)*100 -> 4.6174206 | K12: =I12/$I$38*100 -> 2.8816372
A13: 11 | B13: Kabupaten Sukoharjo | C13: 33951.06 | D13: =((C13-'2024'!C13)/'2024'!C13)*100 -> 5.4793163 | G13: 11 | H13: Kabupaten Sukoharjo | I13: 33951.06 | J13: =((I13-'2024'!H13)/'2024'!H13)*100 -> 5.4758755 | K13: =I13/$I$38*100 -> 2.7848172
A14: 12 | B14: Kabupaten Wonogiri | C14: 26141.91 | D14: =((C14-'2024'!C14)/'2024'!C14)*100 -> 5.7149004 | G14: 12 | H14: Kabupaten Wonogiri | I14: 26141.91 | J14: =((I14-'2024'!H14)/'2024'!H14)*100 -> 5.6705019 | K14: =I14/$I$38*100 -> 2.1442759
... A37: 35 | B37: Kota Tegal | C37: 13897.41 | D37: =((C37-'2024'!C37)/'2024'!C37)*100 -> 5.9278032 | G37: 35 | H37: Kota Tegal | I37: 13897.41 | J37: =((I37-'2024'!H37)/'2024'!H37)*100 -> 5.8832538 | K37: =I37/$I$38*100 -> 1.1399275
A38: Provinsi Jawa Tengah | C38: 1219148.6 | D38: =((C38-'2023'!C38)/'2023'!C38)*100 -> 10.666849 | G38: Provinsi Jawa Tengah | I38: 1219148.6 | J38: =((I38-'2024'!H38)/'2024'!H38)*100 -> 5.3716318 | K38: =I38/$I$38*100 -> 100 | M38: 1219148.6
G41: Sektor PDRB Lapangan Usaha Tahun Dasar 2010
F42: II | I42: [Seri 2010] Distribusi PDRB Atas Dasar Harga Berlaku Menurut Lapangan Usaha (Persen)_2025 (Sektor Utama Terbesar)
I43: 2025
G44: A. Pertanian, Kehutanan, dan Perikanan | I44: 0.75
G45: B. Pertambangan dan Penggalian | I45: 0.14
G46: C. Industri Pengolahan | I46: 28.07
G47: D. Pengadaan Listrik dan Gas | I47: 0.09
G48: E. Pengadaan Air, Pengelolaan Sampah, Limbah dan Daur Ulang | I48: 0.07
G49: F. Konstruksi | I49: 27.13
G50: G. Perdagangan Besar dan Eceran; Reparasi Mobil dan Sepeda Motor | I50: 12.88
G51: H. Transportasi dan Pergudangan | I51: 4.6
G52: I. Penyediaan Akomodasi dan Makan Minum | I52: 3.26
G53: J. Informasi dan Komunikasi | I53: 8.91
G54: K. Jasa Keuangan dan Asuransi | I54: 3.74
G55: L. Real Estate | I55: 2.58
... G61: PDRB | I61: 100
F63: III | G63: PDRB Perkapita
G66: PDRB per Kapita Atas Dasar Harga Berlaku (ribu rupiah), 2020-2025
G68: PDRB Perkapita (Ribu Rupiah) | H68: Tahun
H69: 2020 | I69: =H69+1 -> 2021 | J69: =I69+1 -> 2022 | K69: =J69+1 -> 2023 | L69: =K69+1 -> 2024 | M69: =L69+1 -> 2025
G70: (1) | H70: (2) | I70: (3) | J70: (4) | K70: (5) | L70: (6) | M70: (7)
G71: BPS Kota Semarang | H71: 114189 | I71: 123037 | J71: 135328 | K71: 146839 | L71: 156607 | M71: 167236
F74: III | G74: TPT (Tingkat Pengangguran Terbuka)
G77: Tingkat Pengangguran Terbuka (TPT) Menurut Kabupaten/Kota di Jawa Tengah (Persen), 2020-2025
...
